Workbook
Name codes: Specifications!$A$4:$A$5
Name list: Specifications!$A$11:$A$17

Sheet Intended Use
A1: Intended Use
A2: This worksheet is associated with MTB XDR Product QC Testing Procedure (D37339).
A4: Fields in blue must be input electronically.
A5: Fields in green may be entered manually.
A6: Fields in yellow perform calculations.
A9: Mean Ct MPT MPH Evaluation
A10: This tab calculates the mean Ct, MPT, and MPH values for selected sample types and channels (per CLS) and compares them to specifications on "Specifications" tab. Failing results are highlighted in RED.
A11: This tab performs the same calculations for the "First 10" results | N11: Table of Tabs to Print
A12: Vacuum Seal Data | N12: Tab | O12: Print or Not Print
A13: This tab is used to record and evaluate the Vacuum Seal Test data from ROBAL in-process testing. | N13: Intended Use | O13: Do NOT print
B14: Column A | N14: Mean Ct MPT MPH Evaluation | O14: Print
B15: Enumerates the sampled cartridges. | N15: Vacuum Seal Data | O15: Print
N16: Test Summary | O16: Print
B17: Column B | N17: Data Summary | O17: Print
B18: Records the Cartridge ID. | N18: Data- First 10 | O18: Print
N19: Data- Sample Type 0 | O19: Print
B20: Column C | N20: Data- Sample Type 1 | O20: Print
B21: Records the results of seal test. | N21: Data- Sample Type 2 | O21: Print
B22: Valid entries are: | N22: Data- Replaced | O22: Print
C23: "P" | N23: Statistical Process Control | O23: Print
C24: "F" | N24: Resample Mean Ct MPT MPH Evaluation | O24: Print if applicable
C25: "N" | N25: Resample Data Summary | O25: Print if applicable
N26: Data- Resample Replaced | O26: Print if applicable
B27: Column D | N27: Specifications | O27: Do NOT print
B28: Calculates the results of seal test. | N28: HistoricalAccuStats | O28: Do NOT print
B29: The result is "NA" if the test replicate was not tested or does not apply. | N29: For Reference Only | O29: Do NOT print
B30: The results of the calculations are used as a counter for internal worksheet purposes.
A31: Test Summary
A32: B3 | B32: Select Catalog Number from pull down menu
A33: B4 | B33: Enter lot number (without leading 0)
A34: Row 9 and 12 | B34: Enter Control lot number
A35: Row 15-16 | B35: Enter pipet information
A36: Row 18-21 | B36: Enter GeneXpert information
A37: P18 | B37: Enter bags tested using infinity
A39: A23-G32 | B39: Table 4
B40: column C | C40: Counts individual error types from data summary tab
B41: column D | C41: Compares number of failures to pass/resample criteria (N>4 resample)
B42: column E | C42: Counts individual error types from resample data summary tab
B43: coulmn F | C43: Compares number of failures to pass/resample criteria (N>10 resample)
A44: C34 | B44: Counts the max count for Single Minor Failure
...

Sheet Mean Ct MPT MPH Evaluation
E1: Sample Type 0 (Negative) | J1: Sample Type 1 (WT) | AW1: Sample Type 2 (Mutant)
A2: Data Set | B2: SPC Ct | C2: SPC Ct Mean | E2: Data Set | F2: SPC Ct | G2: SPC mean per Data Set | J2: Data Set | K2: inhA MPT | M2: inhA Ct | O2: katG MPT | Q2: katG MPH | S2: fabG MPT | U2: fabG MPH | W2: fabG Ct | Y2: ahpC MPT | AA2: gyrA1 Ct | AC2: gyrA2 MPT | AE2: gyrA2 MPH | AG2: gyrA3 MPT | AI2: gyrA3 MPH | AK2: gyrB2 MPT | AM2: gyrB2 MPH | AO2: gyrB2 Ct | AQ2: rrs Ct | AS2: eis Ct | AW2: Data Set | AX2: inhA mut MPT | AZ2: katG mut MPT | BB2: katG mut MPH | BD2: fabG mut MPT | BF2: fabG mut MPH | BH2: fabG Ct | BJ2: ahpC mut MPT | BL2: gyrA2 mut MPT | BN2: gyrA3 mut B MPT | BP2: gyrA3 mut B MPH | BR2: gyrB2 mut MPT | BT2: gyrB2 mut MPH | BV2: rrs Ct | BX2: eis Ct
A3: First 10 | B3: =IF('Data Summary'!C10="PASS",'Data - First 10'!Q2,"") -> 26.8 | C3: =AVERAGE(B3:B12) -> 26.82 | E3: 1 | F3: =IF('Data Summary'!C25="PASS",IF('Data Summary'!A25="","",'Data - Sample Type 0'!Q2),"") -> 26.9 | G3: =AVERAGE(F3:F12) -> 27.41 | J3: 1 | K3: =IF(AND('Data Summary'!C130="PASS",'Data - Sample Type 1'!FO2<>0),'Data - Sample Type 1'!FO2,"") -> 76.1 | L3: =AVERAGE(K3:K10) -> 75.9875 | M3: =IF('Data Summary'!C130="PASS",IF('Data - Sample Type 1'!AE2=0,"",'Data - Sample Type 1'!AE2),"") -> 25.9 | N3: =AVERAGE(M3:M10) -> 25.2375 | O3: =IF(AND('Data Summary'!C130="PASS",'Data - Sample Type 1'!FW2<>0),'Data - Sample Type 1'!FW2,"") -> 73.5 | P3: =AVERAGE(O3:O10) -> 73.4 | Q3: =IF(AND('Data Summary'!C130="PASS",O3<>""),'Data - Sample Type 1'!FX2,"") -> 103.1 | R3: =AVERAGE(Q3:Q10) -> 96.6 | S3: =IF(AND('Data Summary'!C130="PASS",'Data - Sample Type 1'!GE2<>0),'Data - Sample Type 1'!GE2,"") -> 71.3 | T3: =AVERAGE(S3:S10) -> 71.2125 | U3: =IF(AND('Data Summary'!C130="PASS",S3<>""),'Data - Sample Type 1'!GF2,"") -> 293.8 | V3: =AVERAGE(U3:U10) -> 267.4625 | W3: =IF('Data Summary'!C130="PASS",IF('Data - Sample Type 1'!BG2=0,"",'Data - Sample Type 1'!BG2),"") -> 24.1 | X3: =AVERAGE(W3:W10) -> 22.25 | Y3: =IF(AND('Data Summary'!C130="PASS",'Data - Sample Type 1'!GM2<>0),'Data - Sample Type 1'!GM2,"") -> 68.5 | Z3: =AVERAGE(Y3:Y10) -> 68.4125 | AA3: =IF('Data Summary'!C130="PASS",IF('Data - Sample Type 1'!BU2=0,"",'Data - Sample Type 1'!BU2),"") -> 30.9 | AB3: =AVERAGE(AA3:AA10) -> 29.3125 | AC3: =IF(AND('Data Summary'!C130="PASS",'Data - Sample Type 1'!HC2<>0),'Data - Sample Type 1'!HC2,"") -> 70.2 | AD3: =AVERAGE(AC3:AC10) -> 70.175 | AE3: =IF(AND('Data Summary'!C130="PASS",AC3<>""),'Data - Sample Type 1'!HD2,"") -> 80.9 | AF3: =AVERAGE(AE3:AE10) -> 82.925 | AG3: =IF(AND('Data Summary'!C130="PASS",'Data - Sample Type 1'!HK2<>0),'Data - Sample Type 1'!HK2,"") -> 70.8 | AH3: =AVERAGE(AG3:AG10) -> 70.825 | AI3: =IF(AND('Data Summary'!C130="PASS",AG3<>""),'Data - Sample Type 1'!HL2,"") -> 138.1 | AJ3: =AVERAGE(AI3:AI10) -> 142.4125 | AK3: =IF(AND('Data Summary'!C130="PASS",'Data - Sample Type 1'!HS2<>0),'Data - Sample Type 1'!HS2,"") -> 69.3 | AL3: =AVERAGE(AK3:AK10) -> 69.1625 | AM3: =IF(AND('Data Summary'!C130="PASS",AK3<>""),'Data - Sample Type 1'!HT2,"") -> 92.7 | AN3: =AVERAGE(AM3:AM10) -> 96.425 | AO3: =IF('Data Summary'!C130="PASS",IF('Data - Sample Type 1'!DK2=0,"",'Data - Sample Type 1'!DK2),"") -> 25.3 | AP3: =AVERAGE(AO3:AO10) -> 23.7625 | AQ3: =IF('Data Summary'!C130="PASS",IF('Data - Sample Type 1'!DY2=0,"",'Data - Sample Type 1'!DY2),"") -> 22.5 | AR3: =AVERAGE(AQ3:AQ10) -> 21.275 | AS3: =IF('Data Summary'!C130="PASS",IF('Data - Sample Type 1'!EM2=0,"",'Data - Sample Type 1'!EM2),"") -> 26.7 | AT3: =AVERAGE(AS3:AS10) -> 24.542857 | AW3: 1-5 | AX3: =IF(AND('Data Summary'!C215="PASS",'Data - Sample Type 2'!IQ2<>0),'Data - Sample Type 2'!IQ2,"") | AY3: =AVERAGE(AX3:AX12) -> 70.466667 | AZ3: =IF(AND('Data Summary'!C215="PASS",'Data - Sample Type 2'!IY2<>0),'Data - Sample Type 2'!IY2,"") | BA3: =AVERAGE(AZ3:AZ12) -> 67.783333 | BB3: =IF(AND('Data Summary'!C215="PASS",AZ3<>""),'Data - Sample Type 2'!IZ2,"") | BC3: =ROUND(AVERAGE(BB3:BB12),0) -> 142 | BD3: =IF(AND('Data Summary'!C215="PASS",'Data - Sample Type 2'!JG2<>0),'Data - Sample Type 2'!JG2,"") | BE3: =AVERAGE(BD3:BD12) -> 75.42 | BF3: =IF(AND('Data Summary'!C215="PASS",BD3<>""),'Data - Sample Type 2'!JH2,"") | BG3: =ROUND(AVERAGE(BF3:BF12),0) -> 168 | BH3: =IF('Data Summary'!C215="PASS",IF('Data - Sample Type 2'!BG2=0,"",'Data - Sample Type 2'!BG2),"") | BI3: =AVERAGE(BH3:BH12) -> 21.983333 | BJ3: =IF(AND('Data Summary'!C215="PASS",'Data - Sample Type 2'!JO2<>0),'Data - Sample Type 2'!JO2,"") | BK3: =AVERAGE(BJ3:BJ12) -> 65.55 | BL3: =IF(AND('Data Summary'!C215="PASS",'Data - Sample Type 2'!HC2<>0),'Data - Sample Type 2'!HC2,"") | BM3: =AVERAGE(BL3:BL12) -> 69.2 | BN3: =IF(AND('Data Summary'!C215="PASS",'Data - Sample Type 2'!LS2<>0),'Data - Sample Type 2'!LS2,"") | BO3: =AVERAGE(BN3:BN12) -> 75.533333 | BP3: =IF(AND('Data Summary'!C215="PASS",BN3<>""),'Data - Sample Type 2'!LT2,"") | BQ3: =ROUND(AVERAGE(BP3:BP12),0) -> 124 | BR3: =IF(AND('Data Summary'!C215="PASS",'Data - Sample Type 2'!MI2<>0),'Data - Sample Type 2'!MI2,"") | BS3: =AVERAGE(BR3:BR12) -> 65.4 | BT3: =IF(AND('Data Summary'!C215="PASS",BR3<>""),'Data - Sample Type 2'!MJ2,"") | BU3: =ROUND(AVERAGE(BT3:BT12),0) -> 101 | BV3: =IF('Data Summary'!C215="PASS",IF('Data - Sample Type 2'!DY2=0,"",'Data - Sample Type 2'!DY2),"") | BW3: =AVERAGE(BV3:BV12) -> 23.266667 | BX3: =IF('Data Summary'!C215="PASS",IF('Data - Sample Type 2'!EM2=0,"",'Data - Sample Type 2'!EM2),"") | BY3: =AVERAGE(BX3:BX12) -> 23.616667
B4: =IF('Data Summary'!C11="PASS",'Data - First 10'!Q3,"") -> 26.2 | F4: =IF('Data Summary'!C26="PASS",IF('Data Summary'!A26="","",'Data - Sample Type 0'!Q3),"") -> 28 | K4: =IF(AND('Data Summary'!C131="PASS",'Data - Sample Type 1'!FO3<>0),'Data - Sample Type 1'!FO3,"") -> 75.9 | M4: =IF('Data Summary'!C131="PASS",IF('Data - Sample Type 1'!AE3=0,"",'Data - Sample Type 1'!AE3),"") -> 25.2 | O4: =IF(AND('Data Summary'!C131="PASS",'Data - Sample Type 1'!FW3<>0),'Data - Sample Type 1'!FW3,"") -> 73.3 | Q4: =IF(AND('Data Summary'!C131="PASS",O4<>""),'Data - Sample Type 1'!FX3,"") -> 91.9 | S4: =IF(AND('Data Summary'!C131="PASS",'Data - Sample Type 1'!GE3<>0),'Data - Sample Type 1'!GE3,"") -> 71.1 | U4: =IF(AND('Data Summary'!C131="PASS",S4<>""),'Data - Sample Type 1'!GF3,"") -> 234.9 | W4: =IF('Data Summary'!C131="PASS",IF('Data - Sample Type 1'!BG3=0,"",'Data - Sample Type 1'!BG3),"") -> 23.2 | Y4: =IF(AND('Data Summary'!C131="PASS",'Data - Sample Type 1'!GM3<>0),'Data - Sample Type 1'!GM3,"") -> 68.3 | AA4: =IF('Data Summary'!C131="PASS",IF('Data - Sample Type 1'!BU3=0,"",'Data - Sample Type 1'!BU3),"") -> 29.6 | AC4: =IF(AND('Data Summary'!C131="PASS",'Data - Sample Type 1'!HC3<>0),'Data - Sample Type 1'!HC3,"") -> 70.1 | AE4: =IF(AND('Data Summary'!C131="PASS",AC4<>""),'Data - Sample Type 1'!HD3,"") -> 81.8 | AG4: =IF(AND('Data Summary'!C131="PASS",'Data - Sample Type 1'!HK3<>0),'Data - Sample Type 1'!HK3,"") -> 70.8 | AI4: =IF(AND('Data Summary'!C131="PASS",AG4<>""),'Data - Sample Type 1'!HL3,"") -> 131.1 | AK4: =IF(AND('Data Summary'!C131="PASS",'Data - Sample Type 1'!HS3<>0),'Data - Sample Type 1'!HS3,"") -> 69.1 | AM4: =IF(AND('Data Summary'!C131="PASS",AK4<>""),'Data - Sample Type 1'!HT3,"") -> 91.1 | AO4: =IF('Data Summary'!C131="PASS",IF('Data - Sample Type 1'!DK3=0,"",'Data - Sample Type 1'!DK3),"") -> 24 | AQ4: =IF('Data Summary'!C131="PASS",IF('Data - Sample Type 1'!DY3=0,"",'Data - Sample Type 1'!DY3),"") -> 21.3 | AS4: =IF('Data Summary'!C131="PASS",IF('Data - Sample Type 1'!EM3=0,"",'Data - Sample Type 1'!EM3),"") -> 24.4 | AX4: =IF(AND('Data Summary'!C216="PASS",'Data - Sample Type 2'!IQ3<>0),'Data - Sample Type 2'!IQ3,"") -> 70.6 | AZ4: =IF(AND('Data Summary'!C216="PASS",'Data - Sample Type 2'!IY3<>0),'Data - Sample Type 2'!IY3,"") -> 67.9 | BB4: =IF(AND('Data Summary'!C216="PASS",AZ4<>""),'Data - Sample Type 2'!IZ3,"") -> 138.9 | BD4: =IF(AND('Data Summary'!C216="PASS",'Data - Sample Type 2'!JG3<>0),'Data - Sample Type 2'!JG3,"") -> 75.5 | BF4: =IF(AND('Data Summary'!C216="PASS",BD4<>""),'Data - Sample Type 2'!JH3,"") -> 176.2 | BH4: =IF('Data Summary'!C216="PASS",IF('Data - Sample Type 2'!BG3=0,"",'Data - Sample Type 2'!BG3),"") -> 24.4 | BJ4: =IF(AND('Data Summary'!C216="PASS",'Data - Sample Type 2'!JO3<>0),'Data - Sample Type 2'!JO3,"") -> 65.7 | BL4: =IF(AND('Data Summary'!C216="PASS",'Data - Sample Type 2'!HC3<>0),'Data - Sample Type 2'!HC3,"") -> 69.2 | BN4: =IF(AND('Data Summary'!C216="PASS",'Data - Sample Type 2'!LS3<>0),'Data - Sample Type 2'!LS3,"") -> 75.6 | BP4: =IF(AND('Data Summary'!C216="PASS",BN4<>""),'Data - Sample Type 2'!LT3,"") -> 136.4 | BR4: =IF(AND('Data Summary'!C216="PASS",'Data - Sample Type 2'!MI3<>0),'Data - Sample Type 2'!MI3,"") -> 65.5 | BT4: =IF(AND('Data Summary'!C216="PASS",BR4<>""),'Data - Sample Type 2'!MJ3,"") -> 90.2 | BV4: =IF('Data Summary'!C216="PASS",IF('Data - Sample Type 2'!DY3=0,"",'Data - Sample Type 2'!DY3),"") -> 24.7 | BX4: =IF('Data Summary'!C216="PASS",IF('Data - Sample Type 2'!EM3=0,"",'Data - Sample Type 2'!EM3),"") -> 24.3
B5: =IF('Data Summary'!C12="PASS",'Data - First 10'!Q4,"") -> 26.3 | F5: =IF('Data Summary'!C27="PASS",IF('Data Summary'!A27="","",'Data - Sample Type 0'!Q4),"") -> 26.5 | K5: =IF(AND('Data Summary'!C132="PASS",'Data - Sample Type 1'!FO4<>0),'Data - Sample Type 1'!FO4,"") -> 75.8 | M5: =IF('Data Summary'!C132="PASS",IF('Data - Sample Type 1'!AE4=0,"",'Data - Sample Type 1'!AE4),"") -> 25.1 | O5: =IF(AND('Data Summary'!C132="PASS",'Data - Sample Type 1'!FW4<>0),'Data - Sample Type 1'!FW4,"") -> 73.2 | Q5: =IF(AND('Data Summary'!C132="PASS",O5<>""),'Data - Sample Type 1'!FX4,"") -> 96.1 | S5: =IF(AND('Data Summary'!C132="PASS",'Data - Sample Type 1'!GE4<>0),'Data - Sample Type 1'!GE4,"") -> 71.1 | U5: =IF(AND('Data Summary'!C132="PASS",S5<>""),'Data - Sample Type 1'!GF4,"") -> 273.5 | W5: =IF('Data Summary'!C132="PASS",IF('Data - Sample Type 1'!BG4=0,"",'Data - Sample Type 1'!BG4),"") -> 17.6 | Y5: =IF(AND('Data Summary'!C132="PASS",'Data - Sample Type 1'!GM4<>0),'Data - Sample Type 1'!GM4,"") -> 68.3 | AA5: =IF('Data Summary'!C132="PASS",IF('Data - Sample Type 1'!BU4=0,"",'Data - Sample Type 1'!BU4),"") -> 28.4 | AC5: =IF(AND('Data Summary'!C132="PASS",'Data - Sample Type 1'!HC4<>0),'Data - Sample Type 1'!HC4,"") -> 70 | AE5: =IF(AND('Data Summary'!C132="PASS",AC5<>""),'Data - Sample Type 1'!HD4,"") -> 69.2 | AG5: =IF(AND('Data Summary'!C132="PASS",'Data - Sample Type 1'!HK4<>0),'Data - Sample Type 1'!HK4,"") -> 70.7 | AI5: =IF(AND('Data Summary'!C132="PASS",AG5<>""),'Data - Sample Type 1'!HL4,"") -> 152.6 | AK5: =IF(AND('Data Summary'!C132="PASS",'Data - Sample Type 1'!HS4<>0),'Data - Sample Type 1'!HS4,"") -> 69.1 | AM5: =IF(AND('Data Summary'!C132="PASS",AK5<>""),'Data - Sample Type 1'!HT4,"") -> 109.3 | AO5: =IF('Data Summary'!C132="PASS",IF('Data - Sample Type 1'!DK4=0,"",'Data - Sample Type 1'!DK4),"") -> 23.1 | AQ5: =IF('Data Summary'!C132="PASS",IF('Data - Sample Type 1'!DY4=0,"",'Data - Sample Type 1'!DY4),"") -> 20.8 | AS5: =IF('Data Summary'!C132="PASS",IF('Data - Sample Type 1'!EM4=0,"",'Data - Sample Type 1'!EM4),"") | AX5: =IF(AND('Data Summary'!C217="PASS",'Data - Sample Type 2'!IQ4<>0),'Data - Sample Type 2'!IQ4,"") -> 70.4 | AZ5: =IF(AND('Data Summary'!C217="PASS",'Data - Sample Type 2'!IY4<>0),'Data - Sample Type 2'!IY4,"") -> 67.7 | BB5: =IF(AND('Data Summary'!C217="PASS",AZ5<>""),'Data - Sample Type 2'!IZ4,"") -> 144.6 | BD5: =IF(AND('Data Summary'!C217="PASS",'Data - Sample Type 2'!JG4<>0),'Data - Sample Type 2'!JG4,"") -> 75.3 | BF5: =IF(AND('Data Summary'!C217="PASS",BD5<>""),'Data - Sample Type 2'!JH4,"") -> 153.3 | BH5: =IF('Data Summary'!C217="PASS",IF('Data - Sample Type 2'!BG4=0,"",'Data - Sample Type 2'!BG4),"") -> 18 | BJ5: =IF(AND('Data Summary'!C217="PASS",'Data - Sample Type 2'!JO4<>0),'Data - Sample Type 2'!JO4,"") -> 65.5 | BL5: =IF(AND('Data Summary'!C217="PASS",'Data - Sample Type 2'!HC4<>0),'Data - Sample Type 2'!HC4,"") -> 68.8 | BN5: =IF(AND('Data Summary'!C217="PASS",'Data - Sample Type 2'!LS4<>0),'Data - Sample Type 2'!LS4,"") -> 75.5 | BP5: =IF(AND('Data Summary'!C217="PASS",BN5<>""),'Data - Sample Type 2'!LT4,"") -> 125.8 | BR5: =IF(AND('Data Summary'!C217="PASS",'Data - Sample Type 2'!MI4<>0),'Data - Sample Type 2'!MI4,"") -> 65.4 | BT5: =IF(AND('Data Summary'!C217="PASS",BR5<>""),'Data - Sample Type 2'!MJ4,"") -> 115.9 | BV5: =IF('Data Summary'!C217="PASS",IF('Data - Sample Type 2'!DY4=0,"",'Data - Sample Type 2'!DY4),"") -> 22.6 | BX5: =IF('Data Summary'!C217="PASS",IF('Data - Sample Type 2'!EM4=0,"",'Data - Sample Type 2'!EM4),"") -> 23.8
B6: =IF('Data Summary'!C13="PASS",'Data - First 10'!Q5,"") -> 26.4 | F6: =IF('Data Summary'!C28="PASS",IF('Data Summary'!A28="","",'Data - Sample Type 0'!Q5),"") -> 26.8 | K6: =IF(AND('Data Summary'!C133="PASS",'Data - Sample Type 1'!FO5<>0),'Data - Sample Type 1'!FO5,"") -> 76 | M6: =IF('Data Summary'!C133="PASS",IF('Data - Sample Type 1'!AE5=0,"",'Data - Sample Type 1'!AE5),"") -> 24.4 | O6: =IF(AND('Data Summary'!C133="PASS",'Data - Sample Type 1'!FW5<>0),'Data - Sample Type 1'!FW5,"") -> 73.4 | Q6: =IF(AND('Data Summary'!C133="PASS",O6<>""),'Data - Sample Type 1'!FX5,"") -> 97.4 | S6: =IF(AND('Data Summary'!C133="PASS",'Data - Sample Type 1'!GE5<>0),'Data - Sample Type 1'!GE5,"") -> 71.2 | U6: =IF(AND('Data Summary'!C133="PASS",S6<>""),'Data - Sample Type 1'!GF5,"") -> 266.4 | W6: =IF('Data Summary'!C133="PASS",IF('Data - Sample Type 1'!BG5=0,"",'Data - Sample Type 1'!BG5),"") -> 22 | Y6: =IF(AND('Data Summary'!C133="PASS",'Data - Sample Type 1'!GM5<>0),'Data - Sample Type 1'!GM5,"") -> 68.4 | AA6: =IF('Data Summary'!C133="PASS",IF('Data - Sample Type 1'!BU5=0,"",'Data - Sample Type 1'!BU5),"") -> 28.4 | AC6: =IF(AND('Data Summary'!C133="PASS",'Data - Sample Type 1'!HC5<>0),'Data - Sample Type 1'!HC5,"") -> 70.2 | AE6: =IF(AND('Data Summary'!C133="PASS",AC6<>""),'Data - Sample Type 1'!HD5,"") -> 82.4 | AG6: =IF(AND('Data Summary'!C133="PASS",'Data - Sample Type 1'!HK5<>0),'Data - Sample Type 1'!HK5,"") -> 70.8 | AI6: =IF(AND('Data Summary'!C133="PASS",AG6<>""),'Data - Sample Type 1'!HL5,"") -> 142.2 | AK6: =IF(AND('Data Summary'!C133="PASS",'Data - Sample Type 1'!HS5<>0),'Data - Sample Type 1'!HS5,"") -> 69.1 | AM6: =IF(AND('Data Summary'!C133="PASS",AK6<>""),'Data - Sample Type 1'!HT5,"") -> 100.6 | AO6: =IF('Data Summary'!C133="PASS",IF('Data - Sample Type 1'!DK5=0,"",'Data - Sample Type 1'!DK5),"") -> 23.3 | AQ6: =IF('Data Summary'!C133="PASS",IF('Data - Sample Type 1'!DY5=0,"",'Data - Sample Type 1'!DY5),"") -> 20.9 | AS6: =IF('Data Summary'!C133="PASS",IF('Data - Sample Type 1'!EM5=0,"",'Data - Sample Type 1'!EM5),"") -> 24 | AX6: =IF(AND('Data Summary'!C218="PASS",'Data - Sample Type 2'!IQ5<>0),'Data - Sample Type 2'!IQ5,"") | AZ6: =IF(AND('Data Summary'!C218="PASS",'Data - Sample Type 2'!IY5<>0),'Data - Sample Type 2'!IY5,"") | BB6: =IF(AND('Data Summary'!C218="PASS",AZ6<>""),'Data - Sample Type 2'!IZ5,"") | BD6: =IF(AND('Data Summary'!C218="PASS",'Data - Sample Type 2'!JG5<>0),'Data - Sample Type 2'!JG5,"") | BF6: =IF(AND('Data Summary'!C218="PASS",BD6<>""),'Data - Sample Type 2'!JH5,"") | BH6: =IF('Data Summary'!C218="PASS",IF('Data - Sample Type 2'!BG5=0,"",'Data - Sample Type 2'!BG5),"") | BJ6: =IF(AND('Data Summary'!C218="PASS",'Data - Sample Type 2'!JO5<>0),'Data - Sample Type 2'!JO5,"") | BL6: =IF(AND('Data Summary'!C218="PASS",'Data - Sample Type 2'!HC5<>0),'Data - Sample Type 2'!HC5,"") | BN6: =IF(AND('Data Summary'!C218="PASS",'Data - Sample Type 2'!LS5<>0),'Data - Sample Type 2'!LS5,"") | BP6: =IF(AND('Data Summary'!C218="PASS",BN6<>""),'Data - Sample Type 2'!LT5,"") | BR6: =IF(AND('Data Summary'!C218="PASS",'Data - Sample Type 2'!MI5<>0),'Data - Sample Type 2'!MI5,"") | BT6: =IF(AND('Data Summary'!C218="PASS",BR6<>""),'Data - Sample Type 2'!MJ5,"") | BV6: =IF('Data Summary'!C218="PASS",IF('Data - Sample Type 2'!DY5=0,"",'Data - Sample Type 2'!DY5),"") | BX6: =IF('Data Summary'!C218="PASS",IF('Data - Sample Type 2'!EM5=0,"",'Data - Sample Type 2'!EM5),"")
B7: =IF('Data Summary'!C14="PASS",'Data - First 10'!Q6,"") -> 25.7 | F7: =IF('Data Summary'!C29="PASS",IF('Data Summary'!A29="","",'Data - Sample Type 0'!Q6),"") -> 29 | K7: =IF(AND('Data Summary'!C134="PASS",'Data - Sample Type 1'!FO6<>0),'Data - Sample Type 1'!FO6,"") -> 75.9 | L7: =IF(AND(L3>=Specifications!$C$21,L3<=Specifications!$D$21),"PASS","FAIL") -> PASS | M7: =IF('Data Summary'!C134="PASS",IF('Data - Sample Type 1'!AE6=0,"",'Data - Sample Type 1'!AE6),"") -> 28 | N7: =IF(N3<=Specifications!D$22,"PASS","FAIL") -> PASS | O7: =IF(AND('Data Summary'!C134="PASS",'Data - Sample Type 1'!FW6<>0),'Data - Sample Type 1'!FW6,"") -> 73.3 | P7: =IF(AND(P3>=Specifications!$C$23,P3<=Specifications!$D$23),"PASS","FAIL") -> PASS | Q7: =IF(AND('Data Summary'!C134="PASS",O7<>""),'Data - Sample Type 1'!FX6,"") -> 99.6 | R7: FIO | S7: =IF(AND('Data Summary'!C134="PASS",'Data - Sample Type 1'!GE6<>0),'Data - Sample Type 1'!GE6,"") -> 71.1 | T7: =IF(AND(T3>=Specifications!$C$25,T3<=Specifications!$D$25),"PASS","FAIL") -> PASS | U7: =IF(AND('Data Summary'!C134="PASS",S7<>""),'Data - Sample Type 1'!GF6,"") -> 274.4 | V7: FIO | W7: =IF('Data Summary'!C134="PASS",IF('Data - Sample Type 1'!BG6=0,"",'Data - Sample Type 1'!BG6),"") -> 25 | X7: =IF(X3<=Specifications!D$27,"PASS","FAIL") -> PASS | Y7: =IF(AND('Data Summary'!C134="PASS",'Data - Sample Type 1'!GM6<>0),'Data - Sample Type 1'!GM6,"") -> 68.3 | Z7: =IF(AND(Z3>=Specifications!$C$28,Z3<=Specifications!$D$28),"PASS","FAIL") -> PASS | AA7: =IF('Data Summary'!C134="PASS",IF('Data - Sample Type 1'!BU6=0,"",'Data - Sample Type 1'!BU6),"") -> 31 | AB7: FIO | AC7: =IF(AND('Data Summary'!C134="PASS",'Data - Sample Type 1'!HC6<>0),'Data - Sample Type 1'!HC6,"") -> 70.1 | AD7: =IF(AND(AD3>=Specifications!$C$31,AD3<=Specifications!$D$31),"PASS","FAIL") -> PASS | AE7: =IF(AND('Data Summary'!C134="PASS",AC7<>""),'Data - Sample Type 1'!HD6,"") -> 80.2 | AF7: FIO | AG7: =IF(AND('Data Summary'!C134="PASS",'Data - Sample Type 1'!HK6<>0),'Data - Sample Type 1'!HK6,"") -> 70.8 | AH7: =IF(AND(AH3>=Specifications!$C$33,AH3<=Specifications!$D$33),"PASS","FAIL") -> PASS | AI7: =IF(AND('Data Summary'!C134="PASS",AG7<>""),'Data - Sample Type 1'!HL6,"") -> 145.7 | AJ7: FIO | AK7: =IF(AND('Data Summary'!C134="PASS",'Data - Sample Type 1'!HS6<>0),'Data - Sample Type 1'!HS6,"") -> 69 | AL7: =IF(AND(AL3>=Specifications!$C$35,AL3<=Specifications!$D$35),"PASS","FAIL") -> PASS | AM7: =IF(AND('Data Summary'!C134="PASS",AK7<>""),'Data - Sample Type 1'!HT6,"") -> 89.1 | AN7: FIO | AO7: =IF('Data Summary'!C134="PASS",IF('Data - Sample Type 1'!DK6=0,"",'Data - Sample Type 1'!DK6),"") -> 24.8 | AP7: =IF(AP3<=Specifications!$D$37,"PASS","FAIL") -> PASS | AQ7: =IF('Data Summary'!C134="PASS",IF('Data - Sample Type 1'!DY6=0,"",'Data - Sample Type 1'!DY6),"") -> 22.8 | AR7: =IF(AR3<=Specifications!$D$38,"PASS","FAIL") -> PASS | AS7: =IF('Data Summary'!C134="PASS",IF('Data - Sample Type 1'!EM6=0,"",'Data - Sample Type 1'!EM6),"") -> 25.3 | AT7: =IF(AT3<=Specifications!$D$39,"PASS","FAIL") -> PASS | AX7: =IF(AND('Data Summary'!C219="PASS",'Data - Sample Type 2'!IQ6<>0),'Data - Sample Type 2'!IQ6,"") -> 70.4 | AZ7: =IF(AND('Data Summary'!C219="PASS",'Data - Sample Type 2'!IY6<>0),'Data - Sample Type 2'!IY6,"") -> 67.8 | BB7: =IF(AND('Data Summary'!C219="PASS",AZ7<>""),'Data - Sample Type 2'!IZ6,"") -> 136.8 | BD7: =IF(AND('Data Summary'!C219="PASS",'Data - Sample Type 2'!JG6<>0),'Data - Sample Type 2'!JG6,"") | BF7: =IF(AND('Data Summary'!C219="PASS",BD7<>""),'Data - Sample Type 2'!JH6,"") | BH7: =IF('Data Summary'!C219="PASS",IF('Data - Sample Type 2'!BG6=0,"",'Data - Sample Type 2'!BG6),"") -> 21.7 | BJ7: =IF(AND('Data Summary'!C219="PASS",'Data - Sample Type 2'!JO6<>0),'Data - Sample Type 2'!JO6,"") -> 65.5 | BL7: =IF(AND('Data Summary'!C219="PASS",'Data - Sample Type 2'!HC6<>0),'Data - Sample Type 2'!HC6,"") -> 69.2 | BN7: =IF(AND('Data Summary'!C219="PASS",'Data - Sample Type 2'!LS6<>0),'Data - Sample Type 2'!LS6,"") -> 75.5 | BP7: =IF(AND('Data Summary'!C219="PASS",BN7<>""),'Data - Sample Type 2'!LT6,"") -> 132.8 | BR7: =IF(AND('Data Summary'!C219="PASS",'Data - Sample Type 2'!MI6<>0),'Data - Sample Type 2'!MI6,"") -> 65.3 | BT7: =IF(AND('Data Summary'!C219="PASS",BR7<>""),'Data - Sample Type 2'!MJ6,"") -> 94.4 | BV7: =IF('Data Summary'!C219="PASS",IF('Data - Sample Type 2'!DY6=0,"",'Data - Sample Type 2'!DY6),"") -> 21.6 | BX7: =IF('Data Summary'!C219="PASS",IF('Data - Sample Type 2'!EM6=0,"",'Data - Sample Type 2'!EM6),"") -> 20.8
B8: =IF('Data Summary'!C15="PASS",'Data - First 10'!Q7,"") -> 25.9 | C8: =IF(C3<=Specifications!$G$20,"PASS","FAIL") -> PASS | F8: =IF('Data Summary'!C30="PASS",IF('Data Summary'!A30="","",'Data - Sample Type 0'!Q7),"") -> 28.1 | G8: =IF(G3<=Specifications!$G$20,"PASS","FAIL") -> PASS | K8: =IF(AND('Data Summary'!C135="PASS",'Data - Sample Type 1'!FO7<>0),'Data - Sample Type 1'!FO7,"") -> 76 | M8: =IF('Data Summary'!C135="PASS",IF('Data - Sample Type 1'!AE7=0,"",'Data - Sample Type 1'!AE7),"") -> 26.7 | O8: =IF(AND('Data Summary'!C135="PASS",'Data - Sample Type 1'!FW7<>0),'Data - Sample Type 1'!FW7,"") -> 73.4 | Q8: =IF(AND('Data Summary'!C135="PASS",O8<>""),'Data - Sample Type 1'!FX7,"") -> 95.3 | S8: =IF(AND('Data Summary'!C135="PASS",'Data - Sample Type 1'!GE7<>0),'Data - Sample Type 1'!GE7,"") -> 71.2 | U8: =IF(AND('Data Summary'!C135="PASS",S8<>""),'Data - Sample Type 1'!GF7,"") -> 238.6 | W8: =IF('Data Summary'!C135="PASS",IF('Data - Sample Type 1'!BG7=0,"",'Data - Sample Type 1'!BG7),"") -> 23.3 | Y8: =IF(AND('Data Summary'!C135="PASS",'Data - Sample Type 1'!GM7<>0),'Data - Sample Type 1'!GM7,"") -> 68.4 | AA8: =IF('Data Summary'!C135="PASS",IF('Data - Sample Type 1'!BU7=0,"",'Data - Sample Type 1'!BU7),"") -> 30.7 | AC8: =IF(AND('Data Summary'!C135="PASS",'Data - Sample Type 1'!HC7<>0),'Data - Sample Type 1'!HC7,"") -> 70.1 | AE8: =IF(AND('Data Summary'!C135="PASS",AC8<>""),'Data - Sample Type 1'!HD7,"") -> 78.7 | AG8: =IF(AND('Data Summary'!C135="PASS",'Data - Sample Type 1'!HK7<>0),'Data - Sample Type 1'!HK7,"") -> 70.8 | AI8: =IF(AND('Data Summary'!C135="PASS",AG8<>""),'Data - Sample Type 1'!HL7,"") -> 126.5 | AK8: =IF(AND('Data Summary'!C135="PASS",'Data - Sample Type 1'!HS7<>0),'Data - Sample Type 1'!HS7,"") -> 69.1 | AM8: =IF(AND('Data Summary'!C135="PASS",AK8<>""),'Data - Sample Type 1'!HT7,"") -> 99.3 | AO8: =IF('Data Summary'!C135="PASS",IF('Data - Sample Type 1'!DK7=0,"",'Data - Sample Type 1'!DK7),"") -> 24 | AQ8: =IF('Data Summary'!C135="PASS",IF('Data - Sample Type 1'!DY7=0,"",'Data - Sample Type 1'!DY7),"") -> 21.4 | AS8: =IF('Data Summary'!C135="PASS",IF('Data - Sample Type 1'!EM7=0,"",'Data - Sample Type 1'!EM7),"") -> 25.3 | AX8: =IF(AND('Data Summary'!C220="PASS",'Data - Sample Type 2'!IQ7<>0),'Data - Sample Type 2'!IQ7,"") -> 70.3 | AY8: =IF(AND(AY3>=Specifications!$E$21,AY3<=Specifications!$F$21),"PASS","FAIL") -> PASS | AZ8: =IF(AND('Data Summary'!C220="PASS",'Data - Sample Type 2'!IY7<>0),'Data - Sample Type 2'!IY7,"") -> 67.6 | BA8: =IF(AND(BA3>=Specifications!$E$23,BA3<=Specifications!$F$23),"PASS","FAIL") -> PASS | BB8: =IF(AND('Data Summary'!C220="PASS",AZ8<>""),'Data - Sample Type 2'!IZ7,"") -> 143.4 | BC8: =IF(BC3>=Specifications!$E$24,"PASS","FAIL") -> PASS | BD8: =IF(AND('Data Summary'!C220="PASS",'Data - Sample Type 2'!JG7<>0),'Data - Sample Type 2'!JG7,"") -> 75.4 | BE8: =IF(AND(BE3>=Specifications!$E$25,BE3<=Specifications!$F$25),"PASS","FAIL") -> PASS | BF8: =IF(AND('Data Summary'!C220="PASS",BD8<>""),'Data - Sample Type 2'!JH7,"") -> 172.2 | BG8: =IF(BG3>=Specifications!$E$26,"PASS","FAIL") -> PASS | BH8: =IF('Data Summary'!C220="PASS",IF('Data - Sample Type 2'!BG7=0,"",'Data - Sample Type 2'!BG7),"") -> 21.7 | BI8: =IF(BI3<=Specifications!$F$27,"PASS","FAIL") -> PASS | BJ8: =IF(AND('Data Summary'!C220="PASS",'Data - Sample Type 2'!JO7<>0),'Data - Sample Type 2'!JO7,"") -> 65.3 | BK8: =IF(AND(BK3>=Specifications!$E$28,BK3<=Specifications!$F$28),"PASS","FAIL") -> PASS | BL8: =IF(AND('Data Summary'!C220="PASS",'Data - Sample Type 2'!HC7<>0),'Data - Sample Type 2'!HC7,"") -> 69.2 | BM8: =IF(AND(BM3>=Specifications!$E$31,BM3<=Specifications!$F$31),"PASS","FAIL") -> PASS | BN8: =IF(AND('Data Summary'!C220="PASS",'Data - Sample Type 2'!LS7<>0),'Data - Sample Type 2'!LS7,"") -> 75.5 | BO8: =IF(AND(BO3>=Specifications!$E$33,BO3<=Specifications!$F$33),"PASS","FAIL") -> PASS | BP8: =IF(AND('Data Summary'!C220="PASS",BN8<>""),'Data - Sample Type 2'!LT7,"") -> 104.7 | BQ8: =IF(BQ3>=Specifications!$E$34,"PASS","FAIL") -> PASS | BR8: =IF(AND('Data Summary'!C220="PASS",'Data - Sample Type 2'!MI7<>0),'Data - Sample Type 2'!MI7,"") -> 65.2 | BS8: =IF(AND(BS3>=Specifications!$E$35,BS3<=Specifications!$F$35),"PASS","FAIL") -> PASS | BT8: =IF(AND('Data Summary'!C220="PASS",BR8<>""),'Data - Sample Type 2'!MJ7,"") -> 99.7 | BU8: =IF(BU3>=Specifications!$E$36,"PASS","FAIL") -> PASS | BV8: =IF('Data Summary'!C220="PASS",IF('Data - Sample Type 2'!DY7=0,"",'Data - Sample Type 2'!DY7),"") -> 22.8 | BW8: =IF(BW3<=Specifications!$F$38,"PASS","FAIL") -> PASS | BX8: =IF('Data Summary'!C220="PASS",IF('Data - Sample Type 2'!EM7=0,"",'Data - Sample Type 2'!EM7),"") -> 23.6 | BY8: =IF(BY3<=Specifications!$F$39,"PASS","FAIL") -> PASS
B9: =IF('Data Summary'!C16="PASS",'Data - First 10'!Q8,"") -> 27.4 | F9: =IF('Data Summary'!C31="PASS",IF('Data Summary'!A31="","",'Data - Sample Type 0'!Q8),"") -> 28.9 | K9: =IF(AND('Data Summary'!C136="PASS",'Data - Sample Type 1'!FO8<>0),'Data - Sample Type 1'!FO8,"") -> 76 | M9: =IF('Data Summary'!C136="PASS",IF('Data - Sample Type 1'!AE8=0,"",'Data - Sample Type 1'!AE8),"") -> 21.7 | O9: =IF(AND('Data Summary'!C136="PASS",'Data - Sample Type 1'!FW8<>0),'Data - Sample Type 1'!FW8,"") -> 73.5 | Q9: =IF(AND('Data Summary'!C136="PASS",O9<>""),'Data - Sample Type 1'!FX8,"") -> 95.1 | S9: =IF(AND('Data Summary'!C136="PASS",'Data - Sample Type 1'!GE8<>0),'Data - Sample Type 1'!GE8,"") -> 71.3 | U9: =IF(AND('Data Summary'!C136="PASS",S9<>""),'Data - Sample Type 1'!GF8,"") -> 267.3 | W9: =IF('Data Summary'!C136="PASS",IF('Data - Sample Type 1'!BG8=0,"",'Data - Sample Type 1'!BG8),"") -> 19.7 | Y9: =IF(AND('Data Summary'!C136="PASS",'Data - Sample Type 1'!GM8<>0),'Data - Sample Type 1'!GM8,"") -> 68.5 | AA9: =IF('Data Summary'!C136="PASS",IF('Data - Sample Type 1'!BU8=0,"",'Data - Sample Type 1'!BU8),"") -> 26.4 | AC9: =IF(AND('Data Summary'!C136="PASS",'Data - Sample Type 1'!HC8<>0),'Data - Sample Type 1'!HC8,"") -> 70.3 | AE9: =IF(AND('Data Summary'!C136="PASS",AC9<>""),'Data - Sample Type 1'!HD8,"") -> 95.9 | AG9: =IF(AND('Data Summary'!C136="PASS",'Data - Sample Type 1'!HK8<>0),'Data - Sample Type 1'!HK8,"") -> 70.9 | AI9: =IF(AND('Data Summary'!C136="PASS",AG9<>""),'Data - Sample Type 1'!HL8,"") -> 149.2 | AK9: =IF(AND('Data Summary'!C136="PASS",'Data - Sample Type 1'!HS8<>0),'Data - Sample Type 1'!HS8,"") -> 69.2 | AM9: =IF(AND('Data Summary'!C136="PASS",AK9<>""),'Data - Sample Type 1'!HT8,"") -> 93.4 | AO9: =IF('Data Summary'!C136="PASS",IF('Data - Sample Type 1'!DK8=0,"",'Data - Sample Type 1'!DK8),"") -> 22.7 | AQ9: =IF('Data Summary'!C136="PASS",IF('Data - Sample Type 1'!DY8=0,"",'Data - Sample Type 1'!DY8),"") -> 19.5 | AS9: =IF('Data Summary'!C136="PASS",IF('Data - Sample Type 1'!EM8=0,"",'Data - Sample Type 1'!EM8),"") -> 23.7 | AX9: =IF(AND('Data Summary'!C221="PASS",'Data - Sample Type 2'!IQ8<>0),'Data - Sample Type 2'!IQ8,"") | AZ9: =IF(AND('Data Summary'!C221="PASS",'Data - Sample Type 2'!IY8<>0),'Data - Sample Type 2'!IY8,"") | BB9: =IF(AND('Data Summary'!C221="PASS",AZ9<>""),'Data - Sample Type 2'!IZ8,"") | BD9: =IF(AND('Data Summary'!C221="PASS",'Data - Sample Type 2'!JG8<>0),'Data - Sample Type 2'!JG8,"") | BF9: =IF(AND('Data Summary'!C221="PASS",BD9<>""),'Data - Sample Type 2'!JH8,"") | BH9: =IF('Data Summary'!C221="PASS",IF('Data - Sample Type 2'!BG8=0,"",'Data - Sample Type 2'!BG8),"") | BJ9: =IF(AND('Data Summary'!C221="PASS",'Data - Sample Type 2'!JO8<>0),'Data - Sample Type 2'!JO8,"") | BL9: =IF(AND('Data Summary'!C221="PASS",'Data - Sample Type 2'!HC8<>0),'Data - Sample Type 2'!HC8,"") | BN9: =IF(AND('Data Summary'!C221="PASS",'Data - Sample Type 2'!LS8<>0),'Data - Sample Type 2'!LS8,"") | BP9: =IF(AND('Data Summary'!C221="PASS",BN9<>""),'Data - Sample Type 2'!LT8,"") | BR9: =IF(AND('Data Summary'!C221="PASS",'Data - Sample Type 2'!MI8<>0),'Data - Sample Type 2'!MI8,"") | BT9: =IF(AND('Data Summary'!C221="PASS",BR9<>""),'Data - Sample Type 2'!MJ8,"") | BV9: =IF('Data Summary'!C221="PASS",IF('Data - Sample Type 2'!DY8=0,"",'Data - Sample Type 2'!DY8),"") | BX9: =IF('Data Summary'!C221="PASS",IF('Data - Sample Type 2'!EM8=0,"",'Data - Sample Type 2'!EM8),"")
B10: =IF('Data Summary'!C17="PASS",'Data - First 10'!Q9,"") -> 27.8 | F10: =IF('Data Summary'!C32="PASS",IF('Data Summary'!A32="","",'Data - Sample Type 0'!Q9),"") -> 26.2 | K10: =IF(AND('Data Summary'!C137="PASS",'Data - Sample Type 1'!FO9<>0),'Data - Sample Type 1'!FO9,"") -> 76.2 | M10: =IF('Data Summary'!C137="PASS",IF('Data - Sample Type 1'!AE9=0,"",'Data - Sample Type 1'!AE9),"") -> 24.9 | O10: =IF(AND('Data Summary'!C137="PASS",'Data - Sample Type 1'!FW9<>0),'Data - Sample Type 1'!FW9,"") -> 73.6 | Q10: =IF(AND('Data Summary'!C137="PASS",O10<>""),'Data - Sample Type 1'!FX9,"") -> 94.3 | S10: =IF(AND('Data Summary'!C137="PASS",'Data - Sample Type 1'!GE9<>0),'Data - Sample Type 1'!GE9,"") -> 71.4 | U10: =IF(AND('Data Summary'!C137="PASS",S10<>""),'Data - Sample Type 1'!GF9,"") -> 290.8 | W10: =IF('Data Summary'!C137="PASS",IF('Data - Sample Type 1'!BG9=0,"",'Data - Sample Type 1'!BG9),"") -> 23.1 | Y10: =IF(AND('Data Summary'!C137="PASS",'Data - Sample Type 1'!GM9<>0),'Data - Sample Type 1'!GM9,"") -> 68.6 | AA10: =IF('Data Summary'!C137="PASS",IF('Data - Sample Type 1'!BU9=0,"",'Data - Sample Type 1'!BU9),"") -> 29.1 | AC10: =IF(AND('Data Summary'!C137="PASS",'Data - Sample Type 1'!HC9<>0),'Data - Sample Type 1'!HC9,"") -> 70.4 | AE10: =IF(AND('Data Summary'!C137="PASS",AC10<>""),'Data - Sample Type 1'!HD9,"") -> 94.3 | AG10: =IF(AND('Data Summary'!C137="PASS",'Data - Sample Type 1'!HK9<>0),'Data - Sample Type 1'!HK9,"") -> 71 | AI10: =IF(AND('Data Summary'!C137="PASS",AG10<>""),'Data - Sample Type 1'!HL9,"") -> 153.9 | AK10: =IF(AND('Data Summary'!C137="PASS",'Data - Sample Type 1'!HS9<>0),'Data - Sample Type 1'!HS9,"") -> 69.4 | AM10: =IF(AND('Data Summary'!C137="PASS",AK10<>""),'Data - Sample Type 1'!HT9,"") -> 95.9 | AO10: =IF('Data Summary'!C137="PASS",IF('Data - Sample Type 1'!DK9=0,"",'Data - Sample Type 1'!DK9),"") -> 22.9 | AQ10: =IF('Data Summary'!C137="PASS",IF('Data - Sample Type 1'!DY9=0,"",'Data - Sample Type 1'!DY9),"") -> 21 | AS10: =IF('Data Summary'!C137="PASS",IF('Data - Sample Type 1'!EM9=0,"",'Data - Sample Type 1'!EM9),"") -> 22.4 | AX10: =IF(AND('Data Summary'!C222="PASS",'Data - Sample Type 2'!IQ9<>0),'Data - Sample Type 2'!IQ9,"") -> 70.5 | AZ10: =IF(AND('Data Summary'!C222="PASS",'Data - Sample Type 2'!IY9<>0),'Data - Sample Type 2'!IY9,"") -> 67.8 | BB10: =IF(AND('Data Summary'!C222="PASS",AZ10<>""),'Data - Sample Type 2'!IZ9,"") -> 154.3 | BD10: =IF(AND('Data Summary'!C222="PASS",'Data - Sample Type 2'!JG9<>0),'Data - Sample Type 2'!JG9,"") -> 75.4 | BF10: =IF(AND('Data Summary'!C222="PASS",BD10<>""),'Data - Sample Type 2'!JH9,"") -> 162.8 | BH10: =IF('Data Summary'!C222="PASS",IF('Data - Sample Type 2'!BG9=0,"",'Data - Sample Type 2'!BG9),"") -> 21.9 | BJ10: =IF(AND('Data Summary'!C222="PASS",'Data - Sample Type 2'!JO9<>0),'Data - Sample Type 2'!JO9,"") -> 65.6 | BL10: =IF(AND('Data Summary'!C222="PASS",'Data - Sample Type 2'!HC9<>0),'Data - Sample Type 2'!HC9,"") -> 69.3 | BN10: =IF(AND('Data Summary'!C222="PASS",'Data - Sample Type 2'!LS9<>0),'Data - Sample Type 2'!LS9,"") -> 75.5 | BP10: =IF(AND('Data Summary'!C222="PASS",BN10<>""),'Data - Sample Type 2'!LT9,"") -> 118.1 | BR10: =IF(AND('Data Summary'!C222="PASS",'Data - Sample Type 2'!MI9<>0),'Data - Sample Type 2'!MI9,"") -> 65.5 | BT10: =IF(AND('Data Summary'!C222="PASS",BR10<>""),'Data - Sample Type 2'!MJ9,"") -> 107.5 | BV10: =IF('Data Summary'!C222="PASS",IF('Data - Sample Type 2'!DY9=0,"",'Data - Sample Type 2'!DY9),"") -> 23.7 | BX10: =IF('Data Summary'!C222="PASS",IF('Data - Sample Type 2'!EM9=0,"",'Data - Sample Type 2'!EM9),"") -> 24.9
B11: =IF('Data Summary'!C18="PASS",'Data - First 10'!Q10,"") -> 27.1 | F11: =IF('Data Summary'!C33="PASS",IF('Data Summary'!A33="","",'Data - Sample Type 0'!Q10),"") -> 26.3 | J11: 2 | K11: =IF(AND('Data Summary'!C138="PASS",'Data - Sample Type 1'!FO10<>0),'Data - Sample Type 1'!FO10,"") -> 76.1 | L11: =AVERAGE(K11:K18) -> 76.1125 | M11: =IF('Data Summary'!C138="PASS",IF('Data - Sample Type 1'!AE10=0,"",'Data - Sample Type 1'!AE10),"") -> 24.4 | N11: =AVERAGE(M11:M18) -> 24.65 | O11: =IF(AND('Data Summary'!C138="PASS",'Data - Sample Type 1'!FW10<>0),'Data - Sample Type 1'!FW10,"") -> 73.6 | P11: =AVERAGE(O11:O18) -> 73.5625 | Q11: =IF(AND('Data Summary'!C138="PASS",O11<>""),'Data - Sample Type 1'!FX10,"") -> 108.7 | R11: =AVERAGE(Q11:Q18) -> 89.275 | S11: =IF(AND('Data Summary'!C138="PASS",'Data - Sample Type 1'!GE10<>0),'Data - Sample Type 1'!GE10,"") -> 71.4 | T11: =AVERAGE(S11:S18) -> 71.3375 | U11: =IF(AND('Data Summary'!C138="PASS",S11<>""),'Data - Sample Type 1'!GF10,"") -> 235.6 | V11: =AVERAGE(U11:U18) -> 227.6875 | W11: =IF('Data Summary'!C138="PASS",IF('Data - Sample Type 1'!BG10=0,"",'Data - Sample Type 1'!BG10),"") -> 22.2 | X11: =AVERAGE(W11:W18) -> 21.4125 | Y11: =IF(AND('Data Summary'!C138="PASS",'Data - Sample Type 1'!GM10<>0),'Data - Sample Type 1'!GM10,"") -> 68.5 | Z11: =AVERAGE(Y11:Y18) -> 68.5125 | AA11: =IF('Data Summary'!C138="PASS",IF('Data - Sample Type 1'!BU10=0,"",'Data - Sample Type 1'!BU10),"") -> 29.5 | AB11: =AVERAGE(AA11:AA18) -> 29.025 | AC11: =IF(AND('Data Summary'!C138="PASS",'Data - Sample Type 1'!HC10<>0),'Data - Sample Type 1'!HC10,"") -> 70.4 | AD11: =AVERAGE(AC11:AC18) -> 70.3625 | AE11: =IF(AND('Data Summary'!C138="PASS",AC11<>""),'Data - Sample Type 1'!HD10,"") -> 89.1 | AF11: =AVERAGE(AE11:AE18) -> 81.15 | AG11: =IF(AND('Data Summary'!C138="PASS",'Data - Sample Type 1'!HK10<>0),'Data - Sample Type 1'!HK10,"") -> 71 | AH11: =AVERAGE(AG11:AG18) -> 70.9625 | AI11: =IF(AND('Data Summary'!C138="PASS",AG11<>""),'Data - Sample Type 1'!HL10,"") -> 143.2 | AJ11: =AVERAGE(AI11:AI18) -> 128.1875 | AK11: =IF(AND('Data Summary'!C138="PASS",'Data - Sample Type 1'!HS10<>0),'Data - Sample Type 1'!HS10,"") -> 69.3 | AL11: =AVERAGE(AK11:AK18) -> 69.2875 | AM11: =IF(AND('Data Summary'!C138="PASS",AK11<>""),'Data - Sample Type 1'!HT10,"") -> 86 | AN11: =AVERAGE(AM11:AM18) -> 82.475 | AO11: =IF('Data Summary'!C138="PASS",IF('Data - Sample Type 1'!DK10=0,"",'Data - Sample Type 1'!DK10),"") -> 24.6 | AP11: =AVERAGE(AO11:AO18) -> 24 | AQ11: =IF('Data Summary'!C138="PASS",IF('Data - Sample Type 1'!DY10=0,"",'Data - Sample Type 1'!DY10),"") -> 21.2 | AR11: =AVERAGE(AQ11:AQ18) -> 20.7375 | AS11: =IF('Data Summary'!C138="PASS",IF('Data - Sample Type 1'!EM10=0,"",'Data - Sample Type 1'!EM10),"") -> 25.1 | AT11: =AVERAGE(AS11:AS18) -> 24.6875 | AX11: =IF(AND('Data Summary'!C223="PASS",'Data - Sample Type 2'!IQ10<>0),'Data - Sample Type 2'!IQ10,"") | AZ11: =IF(AND('Data Summary'!C223="PASS",'Data - Sample Type 2'!IY10<>0),'Data - Sample Type 2'!IY10,"") | BB11: =IF(AND('Data Summary'!C223="PASS",AZ11<>""),'Data - Sample Type 2'!IZ10,"") | BD11: =IF(AND('Data Summary'!C223="PASS",'Data - Sample Type 2'!JG10<>0),'Data - Sample Type 2'!JG10,"") | BF11: =IF(AND('Data Summary'!C223="PASS",BD11<>""),'Data - Sample Type 2'!JH10,"") | BH11: =IF('Data Summary'!C223="PASS",IF('Data - Sample Type 2'!BG10=0,"",'Data - Sample Type 2'!BG10),"") | BJ11: =IF(AND('Data Summary'!C223="PASS",'Data - Sample Type 2'!JO10<>0),'Data - Sample Type 2'!JO10,"") | BL11: =IF(AND('Data Summary'!C223="PASS",'Data - Sample Type 2'!HC10<>0),'Data - Sample Type 2'!HC10,"") | BN11: =IF(AND('Data Summary'!C223="PASS",'Data - Sample Type 2'!LS10<>0),'Data - Sample Type 2'!LS10,"") | BP11: =IF(AND('Data Summary'!C223="PASS",BN11<>""),'Data - Sample Type 2'!LT10,"") | BR11: =IF(AND('Data Summary'!C223="PASS",'Data - Sample Type 2'!MI10<>0),'Data - Sample Type 2'!MI10,"") | BT11: =IF(AND('Data Summary'!C223="PASS",BR11<>""),'Data - Sample Type 2'!MJ10,"") | BV11: =IF('Data Summary'!C223="PASS",IF('Data - Sample Type 2'!DY10=0,"",'Data - Sample Type 2'!DY10),"") | BX11: =IF('Data Summary'!C223="PASS",IF('Data - Sample Type 2'!EM10=0,"",'Data - Sample Type 2'!EM10),"")
B12: =IF('Data Summary'!C19="PASS",'Data - First 10'!Q11,"") -> 28.6 | F12: =IF('Data Summary'!C34="PASS",IF('Data Summary'!A34="","",'Data - Sample Type 0'!Q11),"") -> 27.4 | K12: =IF(AND('Data Summary'!C139="PASS",'Data - Sample Type 1'!FO11<>0),'Data - Sample Type 1'!FO11,"") -> 76.1 | M12: =IF('Data Summary'!C139="PASS",IF('Data - Sample Type 1'!AE11=0,"",'Data - Sample Type 1'!AE11),"") -> 24.9 | O12: =IF(AND('Data Summary'!C139="PASS",'Data - Sample Type 1'!FW11<>0),'Data - Sample Type 1'!FW11,"") -> 73.6 | Q12: =IF(AND('Data Summary'!C139="PASS",O12<>""),'Data - Sample Type 1'!FX11,"") -> 76.7 | S12: =IF(AND('Data Summary'!C139="PASS",'Data - Sample Type 1'!GE11<>0),'Data - Sample Type 1'!GE11,"") -> 71.3 | U12: =IF(AND('Data Summary'!C139="PASS",S12<>""),'Data - Sample Type 1'!GF11,"") -> 199.1 | W12: =IF('Data Summary'!C139="PASS",IF('Data - Sample Type 1'!BG11=0,"",'Data - Sample Type 1'!BG11),"") -> 20.8 | Y12: =IF(AND('Data Summary'!C139="PASS",'Data - Sample Type 1'!GM11<>0),'Data - Sample Type 1'!GM11,"") -> 68.4 | AA12: =IF('Data Summary'!C139="PASS",IF('Data - Sample Type 1'!BU11=0,"",'Data - Sample Type 1'!BU11),"") -> 29.8 | AC12: =IF(AND('Data Summary'!C139="PASS",'Data - Sample Type 1'!HC11<>0),'Data - Sample Type 1'!HC11,"") -> 70.4 | AE12: =IF(AND('Data Summary'!C139="PASS",AC12<>""),'Data - Sample Type 1'!HD11,"") -> 69.2 | AG12: =IF(AND('Data Summary'!C139="PASS",'Data - Sample Type 1'!HK11<>0),'Data - Sample Type 1'!HK11,"") -> 71 | AI12: =IF(AND('Data Summary'!C139="PASS",AG12<>""),'Data - Sample Type 1'!HL11,"") -> 143.4 | AK12: =IF(AND('Data Summary'!C139="PASS",'Data - Sample Type 1'!HS11<>0),'Data - Sample Type 1'!HS11,"") -> 69.2 | AM12: =IF(AND('Data Summary'!C139="PASS",AK12<>""),'Data - Sample Type 1'!HT11,"") -> 73.5 | AO12: =IF('Data Summary'!C139="PASS",IF('Data - Sample Type 1'!DK11=0,"",'Data - Sample Type 1'!DK11),"") -> 24.2 | AQ12: =IF('Data Summary'!C139="PASS",IF('Data - Sample Type 1'!DY11=0,"",'Data - Sample Type 1'!DY11),"") -> 20.7 | AS12: =IF('Data Summary'!C139="PASS",IF('Data - Sample Type 1'!EM11=0,"",'Data - Sample Type 1'!EM11),"") -> 24.7 | AX12: =IF(AND('Data Summary'!C224="PASS",'Data - Sample Type 2'!IQ11<>0),'Data - Sample Type 2'!IQ11,"") -> 70.6 | AZ12: =IF(AND('Data Summary'!C224="PASS",'Data - Sample Type 2'!IY11<>0),'Data - Sample Type 2'!IY11,"") -> 67.9 | BB12: =IF(AND('Data Summary'!C224="PASS",AZ12<>""),'Data - Sample Type 2'!IZ11,"") -> 132.8 | BD12: =IF(AND('Data Summary'!C224="PASS",'Data - Sample Type 2'!JG11<>0),'Data - Sample Type 2'!JG11,"") -> 75.5 | BF12: =IF(AND('Data Summary'!C224="PASS",BD12<>""),'Data - Sample Type 2'!JH11,"") -> 173 | BH12: =IF('Data Summary'!C224="PASS",IF('Data - Sample Type 2'!BG11=0,"",'Data - Sample Type 2'!BG11),"") -> 24.2 | BJ12: =IF(AND('Data Summary'!C224="PASS",'Data - Sample Type 2'!JO11<>0),'Data - Sample Type 2'!JO11,"") -> 65.7 | BL12: =IF(AND('Data Summary'!C224="PASS",'Data - Sample Type 2'!HC11<>0),'Data - Sample Type 2'!HC11,"") -> 69.5 | BN12: =IF(AND('Data Summary'!C224="PASS",'Data - Sample Type 2'!LS11<>0),'Data - Sample Type 2'!LS11,"") -> 75.6 | BP12: =IF(AND('Data Summary'!C224="PASS",BN12<>""),'Data - Sample Type 2'!LT11,"") -> 124 | BR12: =IF(AND('Data Summary'!C224="PASS",'Data - Sample Type 2'!MI11<>0),'Data - Sample Type 2'!MI11,"") -> 65.5 | BT12: =IF(AND('Data Summary'!C224="PASS",BR12<>""),'Data - Sample Type 2'!MJ11,"") -> 101 | BV12: =IF('Data Summary'!C224="PASS",IF('Data - Sample Type 2'!DY11=0,"",'Data - Sample Type 2'!DY11),"") -> 24.2 | BX12: =IF('Data Summary'!C224="PASS",IF('Data - Sample Type 2'!EM11=0,"",'Data - Sample Type 2'!EM11),"") -> 24.3
E13: 2 | F13: =IF('Data Summary'!C35="PASS",IF('Data Summary'!A35="","",'Data - Sample Type 0'!Q12),"") -> 27.4 | G13: =AVERAGE(F13:F22) -> 26.79 | K13: =IF(AND('Data Summary'!C140="PASS",'Data - Sample Type 1'!FO12<>0),'Data - Sample Type 1'!FO12,"") -> 76.2 | M13: =IF('Data Summary'!C140="PASS",IF('Data - Sample Type 1'!AE12=0,"",'Data - Sample Type 1'!AE12),"") -> 23.8 | O13: =IF(AND('Data Summary'!C140="PASS",'Data - Sample Type 1'!FW12<>0),'Data - Sample Type 1'!FW12,"") -> 73.6 | Q13: =IF(AND('Data Summary'!C140="PASS",O13<>""),'Data - Sample Type 1'!FX12,"") -> 85.3 | S13: =IF(AND('Data Summary'!C140="PASS",'Data - Sample Type 1'!GE12<>0),'Data - Sample Type 1'!GE12,"") -> 71.4 | U13: =IF(AND('Data Summary'!C140="PASS",S13<>""),'Data - Sample Type 1'!GF12,"") -> 228.2 | W13: =IF('Data Summary'!C140="PASS",IF('Data - Sample Type 1'!BG12=0,"",'Data - Sample Type 1'!BG12),"") -> 18.5 | Y13: =IF(AND('Data Summary'!C140="PASS",'Data - Sample Type 1'!GM12<>0),'Data - Sample Type 1'!GM12,"") -> 68.6 | AA13: =IF('Data Summary'!C140="PASS",IF('Data - Sample Type 1'!BU12=0,"",'Data - Sample Type 1'!BU12),"") -> 27.6 | AC13: =IF(AND('Data Summary'!C140="PASS",'Data - Sample Type 1'!HC12<>0),'Data - Sample Type 1'!HC12,"") -> 70.4 | AE13: =IF(AND('Data Summary'!C140="PASS",AC13<>""),'Data - Sample Type 1'!HD12,"") -> 89.5 | AG13: =IF(AND('Data Summary'!C140="PASS",'Data - Sample Type 1'!HK12<>0),'Data - Sample Type 1'!HK12,"") -> 71 | AI13: =IF(AND('Data Summary'!C140="PASS",AG13<>""),'Data - Sample Type 1'!HL12,"") -> 131.7 | AK13: =IF(AND('Data Summary'!C140="PASS",'Data - Sample Type 1'!HS12<>0),'Data - Sample Type 1'!HS12,"") -> 69.4 | AM13: =IF(AND('Data Summary'!C140="PASS",AK13<>""),'Data - Sample Type 1'!HT12,"") -> 84.2 | AO13: =IF('Data Summary'!C140="PASS",IF('Data - Sample Type 1'!DK12=0,"",'Data - Sample Type 1'!DK12),"") -> 23.5 | AQ13: =IF('Data Summary'!C140="PASS",IF('Data - Sample Type 1'!DY12=0,"",'Data - Sample Type 1'!DY12),"") -> 20 | AS13: =IF('Data Summary'!C140="PASS",IF('Data - Sample Type 1'!EM12=0,"",'Data - Sample Type 1'!EM12),"") -> 24.1 | AW13: 6-10 | AX13: =IF(AND('Data Summary'!C225="PASS",'Data - Sample Type 2'!IQ12<>0),'Data - Sample Type 2'!IQ12,"") -> 70.7 | AY13: =AVERAGE(AX13:AX22) -> 70.766667 | AZ13: =IF(AND('Data Summary'!C225="PASS",'Data - Sample Type 2'!IY12<>0),'Data - Sample Type 2'!IY12,"") -> 68 | BA13: =AVERAGE(AZ13:AZ22) -> 68.077778 | BB13: =IF(AND('Data Summary'!C225="PASS",AZ13<>""),'Data - Sample Type 2'!IZ12,"") -> 130.9 | BC13: =ROUND(AVERAGE(BB13:BB22),0) -> 130 | BD13: =IF(AND('Data Summary'!C225="PASS",'Data - Sample Type 2'!JG12<>0),'Data - Sample Type 2'!JG12,"") -> 75.8 | BE13: =AVERAGE(BD13:BD22) -> 75.688889 | BF13: =IF(AND('Data Summary'!C225="PASS",BD13<>""),'Data - Sample Type 2'!JH12,"") -> 140.5 | BG13: =ROUND(AVERAGE(BF13:BF22),0) -> 154 | BH13: =IF('Data Summary'!C225="PASS",IF('Data - Sample Type 2'!BG12=0,"",'Data - Sample Type 2'!BG12),"") -> 20.9 | BI13: =AVERAGE(BH13:BH22) -> 22.255556 | BJ13: =IF(AND('Data Summary'!C225="PASS",'Data - Sample Type 2'!JO12<>0),'Data - Sample Type 2'!JO12,"") -> 65.8 | BK13: =AVERAGE(BJ13:BJ22) -> 65.877778 | BL13: =IF(AND('Data Summary'!C225="PASS",'Data - Sample Type 2'!HC12<>0),'Data - Sample Type 2'!HC12,"") -> 69.8 | BM13: =AVERAGE(BL13:BL22) -> 69.644444 | BN13: =IF(AND('Data Summary'!C225="PASS",'Data - Sample Type 2'!LS12<>0),'Data - Sample Type 2'!LS12,"") -> 75.9 | BO13: =AVERAGE(BN13:BN22) -> 75.833333 | BP13: =IF(AND('Data Summary'!C225="PASS",BN13<>""),'Data - Sample Type 2'!LT12,"") -> 103.2 | BQ13: =ROUND(AVERAGE(BP13:BP22),0) -> 114 | BR13: =IF(AND('Data Summary'!C225="PASS",'Data - Sample Type 2'!MI12<>0),'Data - Sample Type 2'!MI12,"") -> 65.6 | BS13: =AVERAGE(BR13:BR22) -> 65.688889 | BT13: =IF(AND('Data Summary'!C225="PASS",BR13<>""),'Data - Sample Type 2'!MJ12,"") -> 83.1 | BU13: =ROUND(AVERAGE(BT13:BT22),0) -> 90 | BV13: =IF('Data Summary'!C225="PASS",IF('Data - Sample Type 2'!DY12=0,"",'Data - Sample Type 2'!DY12),"") -> 22.2 | BW13: =AVERAGE(BV13:BV22) -> 23.811111 | BX13: =IF('Data Summary'!C225="PASS",IF('Data - Sample Type 2'!EM12=0,"",'Data - Sample Type 2'!EM12),"") -> 22.2 | BY13: =AVERAGE(BX13:BX22) -> 24.355556
E14: 2 | F14: =IF('Data Summary'!C36="PASS",IF('Data Summary'!A36="","",'Data - Sample Type 0'!Q13),"") -> 27.4 | K14: =IF(AND('Data Summary'!C141="PASS",'Data - Sample Type 1'!FO13<>0),'Data - Sample Type 1'!FO13,"") -> 76.3 | M14: =IF('Data Summary'!C141="PASS",IF('Data - Sample Type 1'!AE13=0,"",'Data - Sample Type 1'!AE13),"") -> 23.4 | O14: =IF(AND('Data Summary'!C141="PASS",'Data - Sample Type 1'!FW13<>0),'Data - Sample Type 1'!FW13,"") -> 73.7 | Q14: =IF(AND('Data Summary'!C141="PASS",O14<>""),'Data - Sample Type 1'!FX13,"") -> 84 | S14: =IF(AND('Data Summary'!C141="PASS",'Data - Sample Type 1'!GE13<>0),'Data - Sample Type 1'!GE13,"") -> 71.4 | U14: =IF(AND('Data Summary'!C141="PASS",S14<>""),'Data - Sample Type 1'!GF13,"") -> 204.2 | W14: =IF('Data Summary'!C141="PASS",IF('Data - Sample Type 1'!BG13=0,"",'Data - Sample Type 1'!BG13),"") -> 21.8 | Y14: =IF(AND('Data Summary'!C141="PASS",'Data - Sample Type 1'!GM13<>0),'Data - Sample Type 1'!GM13,"") -> 68.7 | AA14: =IF('Data Summary'!C141="PASS",IF('Data - Sample Type 1'!BU13=0,"",'Data - Sample Type 1'!BU13),"") -> 27.8 | AC14: =IF(AND('Data Summary'!C141="PASS",'Data - Sample Type 1'!HC13<>0),'Data - Sample Type 1'!HC13,"") -> 70.4 | AE14: =IF(AND('Data Summary'!C141="PASS",AC14<>""),'Data - Sample Type 1'!HD13,"") -> 87.7 | AG14: =IF(AND('Data Summary'!C141="PASS",'Data - Sample Type 1'!HK13<>0),'Data - Sample Type 1'!HK13,"") -> 71 | AI14: =IF(AND('Data Summary'!C141="PASS",AG14<>""),'Data - Sample Type 1'!HL13,"") -> 127.4 | AK14: =IF(AND('Data Summary'!C141="PASS",'Data - Sample Type 1'!HS13<>0),'Data - Sample Type 1'!HS13,"") -> 69.5 | AM14: =IF(AND('Data Summary'!C141="PASS",AK14<>""),'Data - Sample Type 1'!HT13,"") -> 79.8 | AO14: =IF('Data Summary'!C141="PASS",IF('Data - Sample Type 1'!DK13=0,"",'Data - Sample Type 1'!DK13),"") -> 23.1 | AQ14: =IF('Data Summary'!C141="PASS",IF('Data - Sample Type 1'!DY13=0,"",'Data - Sample Type 1'!DY13),"") -> 19.9 | AS14: =IF('Data Summary'!C141="PASS",IF('Data - Sample Type 1'!EM13=0,"",'Data - Sample Type 1'!EM13),"") -> 24.2 | AX14: =IF(AND('Data Summary'!C226="PASS",'Data - Sample Type 2'!IQ13<>0),'Data - Sample Type 2'!IQ13,"") -> 70.7 | AZ14: =IF(AND('Data Summary'!C226="PASS",'Data - Sample Type 2'!IY13<>0),'Data - Sample Type 2'!IY13,"") -> 68 | BB14: =IF(AND('Data Summary'!C226="PASS",AZ14<>""),'Data - Sample Type 2'!IZ13,"") -> 157.9 | BD14: =IF(AND('Data Summary'!C226="PASS",'Data - Sample Type 2'!JG13<>0),'Data - Sample Type 2'!JG13,"") -> 75.7 | BF14: =IF(AND('Data Summary'!C226="PASS",BD14<>""),'Data - Sample Type 2'!JH13,"") -> 151.9 | BH14: =IF('Data Summary'!C226="PASS",IF('Data - Sample Type 2'!BG13=0,"",'Data - Sample Type 2'!BG13),"") -> 22 | BJ14: =IF(AND('Data Summary'!C226="PASS",'Data - Sample Type 2'!JO13<>0),'Data - Sample Type 2'!JO13,"") -> 65.8 | BL14: =IF(AND('Data Summary'!C226="PASS",'Data - Sample Type 2'!HC13<>0),'Data - Sample Type 2'!HC13,"") -> 69.8 | BN14: =IF(AND('Data Summary'!C226="PASS",'Data - Sample Type 2'!LS13<>0),'Data - Sample Type 2'!LS13,"") -> 75.9 | BP14: =IF(AND('Data Summary'!C226="PASS",BN14<>""),'Data - Sample Type 2'!LT13,"") -> 130.9 | BR14: =IF(AND('Data Summary'!C226="PASS",'Data - Sample Type 2'!MI13<>0),'Data - Sample Type 2'!MI13,"") -> 65.6 | BT14: =IF(AND('Data Summary'!C226="PASS",BR14<>""),'Data - Sample Type 2'!MJ13,"") -> 94.3 | BV14: =IF('Data Summary'!C226="PASS",IF('Data - Sample Type 2'!DY13=0,"",'Data - Sample Type 2'!DY13),"") -> 23.5 | BX14: =IF('Data Summary'!C226="PASS",IF('Data - Sample Type 2'!EM13=0,"",'Data - Sample Type 2'!EM13),"") -> 24.2
F15: =IF('Data Summary'!C37="PASS",IF('Data Summary'!A37="","",'Data - Sample Type 0'!Q14),"") -> 25.8 | K15: =IF(AND('Data Summary'!C142="PASS",'Data - Sample Type 1'!FO14<>0),'Data - Sample Type 1'!FO14,"") -> 76 | L15: =IF(AND(L11>=Specifications!$C$21,L11<=Specifications!$D$21),"PASS","FAIL") -> PASS | M15: =IF('Data Summary'!C142="PASS",IF('Data - Sample Type 1'!AE14=0,"",'Data - Sample Type 1'!AE14),"") -> 25.4 | N15: =IF(N11<=Specifications!D$22,"PASS","FAIL") -> PASS | O15: =IF(AND('Data Summary'!C142="PASS",'Data - Sample Type 1'!FW14<>0),'Data - Sample Type 1'!FW14,"") -> 73.5 | P15: =IF(AND(P11>=Specifications!$C$23,P11<=Specifications!$D$23),"PASS","FAIL") -> PASS | Q15: =IF(AND('Data Summary'!C142="PASS",O15<>""),'Data - Sample Type 1'!FX14,"") -> 90.1 | R15: FIO | S15: =IF(AND('Data Summary'!C142="PASS",'Data - Sample Type 1'!GE14<>0),'Data - Sample Type 1'!GE14,"") -> 71.3 | T15: =IF(AND(T11>=Specifications!$C$25,T11<=Specifications!$D$25),"PASS","FAIL") -> PASS | U15: =IF(AND('Data Summary'!C142="PASS",S15<>""),'Data - Sample Type 1'!GF14,"") -> 232.7 | V15: FIO | W15: =IF('Data Summary'!C142="PASS",IF('Data - Sample Type 1'!BG14=0,"",'Data - Sample Type 1'!BG14),"") -> 21.6 | X15: =IF(X11<=Specifications!D$27,"PASS","FAIL") -> PASS | Y15: =IF(AND('Data Summary'!C142="PASS",'Data - Sample Type 1'!GM14<>0),'Data - Sample Type 1'!GM14,"") -> 68.4 | Z15: =IF(AND(Z11>=Specifications!$C$28,Z11<=Specifications!$D$28),"PASS","FAIL") -> PASS | AA15: =IF('Data Summary'!C142="PASS",IF('Data - Sample Type 1'!BU14=0,"",'Data - Sample Type 1'!BU14),"") -> 29.5 | AB15: FIO | AC15: =IF(AND('Data Summary'!C142="PASS",'Data - Sample Type 1'!HC14<>0),'Data - Sample Type 1'!HC14,"") -> 70.3 | AD15: =IF(AND(AD11>=Specifications!$C$31,AD11<=Specifications!$D$31),"PASS","FAIL") -> PASS | AE15: =IF(AND('Data Summary'!C142="PASS",AC15<>""),'Data - Sample Type 1'!HD14,"") -> 74.7 | AF15: FIO | AG15: =IF(AND('Data Summary'!C142="PASS",'Data - Sample Type 1'!HK14<>0),'Data - Sample Type 1'!HK14,"") -> 70.9 | AH15: =IF(AND(AH11>=Specifications!$C$33,AH11<=Specifications!$D$33),"PASS","FAIL") -> PASS | AI15: =IF(AND('Data Summary'!C142="PASS",AG15<>""),'Data - Sample Type 1'!HL14,"") -> 114.8 | AJ15: FIO | AK15: =IF(AND('Data Summary'!C142="PASS",'Data - Sample Type 1'!HS14<>0),'Data - Sample Type 1'!HS14,"") -> 69.2 | AL15: =IF(AND(AL11>=Specifications!$C$35,AL11<=Specifications!$D$35),"PASS","FAIL") -> PASS | AM15: =IF(AND('Data Summary'!C142="PASS",AK15<>""),'Data - Sample Type 1'!HT14,"") -> 84 | AN15: FIO | AO15: =IF('Data Summary'!C142="PASS",IF('Data - Sample Type 1'!DK14=0,"",'Data - Sample Type 1'!DK14),"") -> 23.3 | AP15: =IF(AP11<=Specifications!$D$37,"PASS","FAIL") -> PASS | AQ15: =IF('Data Summary'!C142="PASS",IF('Data - Sample Type 1'!DY14=0,"",'Data - Sample Type 1'!DY14),"") -> 20.9 | AR15: =IF(AR11<=Specifications!$D$38,"PASS","FAIL") -> PASS | AS15: =IF('Data Summary'!C142="PASS",IF('Data - Sample Type 1'!EM14=0,"",'Data - Sample Type 1'!EM14),"") -> 23.8 | AT15: =IF(AT11<=Specifications!$D$39,"PASS","FAIL") -> PASS | AX15: =IF(AND('Data Summary'!C227="PASS",'Data - Sample Type 2'!IQ14<>0),'Data - Sample Type 2'!IQ14,"") -> 70.5 | AZ15: =IF(AND('Data Summary'!C227="PASS",'Data - Sample Type 2'!IY14<>0),'Data - Sample Type 2'!IY14,"") -> 67.8 | BB15: =IF(AND('Data Summary'!C227="PASS",AZ15<>""),'Data - Sample Type 2'!IZ14,"") -> 126.5 | BD15: =IF(AND('Data Summary'!C227="PASS",'Data - Sample Type 2'!JG14<>0),'Data - Sample Type 2'!JG14,"") -> 75.4 | BF15: =IF(AND('Data Summary'!C227="PASS",BD15<>""),'Data - Sample Type 2'!JH14,"") -> 165 | BH15: =IF('Data Summary'!C227="PASS",IF('Data - Sample Type 2'!BG14=0,"",'Data - Sample Type 2'!BG14),"") -> 25 | BJ15: =IF(AND('Data Summary'!C227="PASS",'Data - Sample Type 2'!JO14<>0),'Data - Sample Type 2'!JO14,"") -> 65.7 | BL15: =IF(AND('Data Summary'!C227="PASS",'Data - Sample Type 2'!HC14<>0),'Data - Sample Type 2'!HC14,"") -> 69.5 | BN15: =IF(AND('Data Summary'!C227="PASS",'Data - Sample Type 2'!LS14<>0),'Data - Sample Type 2'!LS14,"") -> 75.5 | BP15: =IF(AND('Data Summary'!C227="PASS",BN15<>""),'Data - Sample Type 2'!LT14,"") -> 120.7 | BR15: =IF(AND('Data Summary'!C227="PASS",'Data - Sample Type 2'!MI14<>0),'Data - Sample Type 2'!MI14,"") -> 65.5 | BT15: =IF(AND('Data Summary'!C227="PASS",BR15<>""),'Data - Sample Type 2'!MJ14,"") -> 88.2 | BV15: =IF('Data Summary'!C227="PASS",IF('Data - Sample Type 2'!DY14=0,"",'Data - Sample Type 2'!DY14),"") -> 25.1 | BX15: =IF('Data Summary'!C227="PASS",IF('Data - Sample Type 2'!EM14=0,"",'Data - Sample Type 2'!EM14),"") -> 25.1
F16: =IF('Data Summary'!C38="PASS",IF('Data Summary'!A38="","",'Data - Sample Type 0'!Q15),"") -> 26.1 | K16: =IF(AND('Data Summary'!C143="PASS",'Data - Sample Type 1'!FO15<>0),'Data - Sample Type 1'!FO15,"") -> 75.6 | M16: =IF('Data Summary'!C143="PASS",IF('Data - Sample Type 1'!AE15=0,"",'Data - Sample Type 1'!AE15),"") -> 27.5 | O16: =IF(AND('Data Summary'!C143="PASS",'Data - Sample Type 1'!FW15<>0),'Data - Sample Type 1'!FW15,"") -> 73.2 | Q16: =IF(AND('Data Summary'!C143="PASS",O16<>""),'Data - Sample Type 1'!FX15,"") -> 87.6 | S16: =IF(AND('Data Summary'!C143="PASS",'Data - Sample Type 1'!GE15<>0),'Data - Sample Type 1'!GE15,"") -> 71 | U16: =IF(AND('Data Summary'!C143="PASS",S16<>""),'Data - Sample Type 1'!GF15,"") -> 228 | W16: =IF('Data Summary'!C143="PASS",IF('Data - Sample Type 1'!BG15=0,"",'Data - Sample Type 1'!BG15),"") -> 22.9 | Y16: =IF(AND('Data Summary'!C143="PASS",'Data - Sample Type 1'!GM15<>0),'Data - Sample Type 1'!GM15,"") -> 68 | AA16: =IF('Data Summary'!C143="PASS",IF('Data - Sample Type 1'!BU15=0,"",'Data - Sample Type 1'!BU15),"") -> 31.5 | AC16: =IF(AND('Data Summary'!C143="PASS",'Data - Sample Type 1'!HC15<>0),'Data - Sample Type 1'!HC15,"") -> 70.2 | AE16: =IF(AND('Data Summary'!C143="PASS",AC16<>""),'Data - Sample Type 1'!HD15,"") -> 75.9 | AG16: =IF(AND('Data Summary'!C143="PASS",'Data - Sample Type 1'!HK15<>0),'Data - Sample Type 1'!HK15,"") -> 70.7 | AI16: =IF(AND('Data Summary'!C143="PASS",AG16<>""),'Data - Sample Type 1'!HL15,"") -> 114.8 | AK16: =IF(AND('Data Summary'!C143="PASS",'Data - Sample Type 1'!HS15<>0),'Data - Sample Type 1'!HS15,"") -> 68.8 | AM16: =IF(AND('Data Summary'!C143="PASS",AK16<>""),'Data - Sample Type 1'!HT15,"") -> 94.5 | AO16: =IF('Data Summary'!C143="PASS",IF('Data - Sample Type 1'!DK15=0,"",'Data - Sample Type 1'!DK15),"") -> 26.1 | AQ16: =IF('Data Summary'!C143="PASS",IF('Data - Sample Type 1'!DY15=0,"",'Data - Sample Type 1'!DY15),"") -> 22.7 | AS16: =IF('Data Summary'!C143="PASS",IF('Data - Sample Type 1'!EM15=0,"",'Data - Sample Type 1'!EM15),"") -> 27.4 | AX16: =IF(AND('Data Summary'!C228="PASS",'Data - Sample Type 2'!IQ15<>0),'Data - Sample Type 2'!IQ15,"") -> 70.8 | AZ16: =IF(AND('Data Summary'!C228="PASS",'Data - Sample Type 2'!IY15<>0),'Data - Sample Type 2'!IY15,"") -> 68.1 | BB16: =IF(AND('Data Summary'!C228="PASS",AZ16<>""),'Data - Sample Type 2'!IZ15,"") -> 119 | BD16: =IF(AND('Data Summary'!C228="PASS",'Data - Sample Type 2'!JG15<>0),'Data - Sample Type 2'!JG15,"") -> 75.7 | BF16: =IF(AND('Data Summary'!C228="PASS",BD16<>""),'Data - Sample Type 2'!JH15,"") -> 156.9 | BH16: =IF('Data Summary'!C228="PASS",IF('Data - Sample Type 2'!BG15=0,"",'Data - Sample Type 2'!BG15),"") -> 24 | BJ16: =IF(AND('Data Summary'!C228="PASS",'Data - Sample Type 2'!JO15<>0),'Data - Sample Type 2'!JO15,"") -> 65.9 | BL16: =IF(AND('Data Summary'!C228="PASS",'Data - Sample Type 2'!HC15<>0),'Data - Sample Type 2'!HC15,"") -> 69.4 | BN16: =IF(AND('Data Summary'!C228="PASS",'Data - Sample Type 2'!LS15<>0),'Data - Sample Type 2'!LS15,"") -> 75.9 | BP16: =IF(AND('Data Summary'!C228="PASS",BN16<>""),'Data - Sample Type 2'!LT15,"") -> 100.9 | BR16: =IF(AND('Data Summary'!C228="PASS",'Data - Sample Type 2'!MI15<>0),'Data - Sample Type 2'!MI15,"") -> 65.7 | BT16: =IF(AND('Data Summary'!C228="PASS",BR16<>""),'Data - Sample Type 2'!MJ15,"") -> 84.3 | BV16: =IF('Data Summary'!C228="PASS",IF('Data - Sample Type 2'!DY15=0,"",'Data - Sample Type 2'!DY15),"") -> 24.3 | BX16: =IF('Data Summary'!C228="PASS",IF('Data - Sample Type 2'!EM15=0,"",'Data - Sample Type 2'!EM15),"") -> 25.4
